Workbook
Name NativeTimeline_order_date: #N/A
Name Slicer_order_status: #N/A

Sheet raw_customers
A1: customer_id | B1: name | C1: email | D1: phone | E1: city | F1: province | G1: registration_date | H1: gender | I1: age_group
A2: CUST0001 | B2: Andi Rahmawati | C2: andirahmawati229@yahoo.com | D2: 82118196001 | E2: Semarang | F2: Jawa Tengah | G2: 44673 | H2: Male | I2: 25-34
A3: CUST0002 | B3: Sari Sembiring | C3: sarisembiring226@gmail.com | D3: 85794026542 | E3: Semarang | F3: Jawa Tengah | G3: 44886 | H3: Female | I3: 18-24
A4: CUST0003 | B4: Bella Aprilia | C4: bellaaprilia271@gmail.com | D4: 81278161849 | E4: Tangerang | F4: Banten | G4: 45379 | H4: Female | I4: 18-24
A5: CUST0004 | B5: Shinta Hartono | C5: shintahartono82@outlook.com | D5: 82216475255 | E5: Semarang | F5: Jawa Tengah | G5: 45569 | H5: Female | I5: 25-34
A6: CUST0005 | B6: Maulana Hidayat | C6: maulanahidayat651@gmail.com | D6: 82183276483 | E6: Bekasi | F6: Jawa Barat | G6: 44311 | H6: Male | I6: 18-24
A7: CUST0006 | B7: Nadia Iskandar | C7: nadiaiskandar68@outlook.com | D7: 82295376724 | E7: Makassar | F7: Sulawesi Selatan | G7: 44702 | H7: Female | I7: 35-44
A8: CUST0007 | B8: Ratna Sari | C8: ratnasari920@gmail.com | D8: 87865328710 | E8: Medan | F8: Sumatera Utara | G8: 44510 | H8: Female | I8: 25-34
A9: CUST0008 | B9: Yoga Utami | C9: yogautami395@gmail.com | D9: 85697848018 | E9: Denpasar | F9: Bali | G9: 45509 | H9: Male | I9: 25-34
A10: CUST0009 | B10: Rani Simbolon | C10: ranisimbolon977@gmail.com | D10: 89648281489 | E10: Semarang | F10: Jawa Tengah | G10: 44510 | H10: Female | I10: 25-34
A11: CUST0010 | B11: Vera Hutapea | C11: verahutapea614@gmail.com | D11: 85370154303 | E11: Manado | F11: Sulawesi Utara | G11: 44358 | H11: Female | I11: 18-24
A12: CUST0011 | B12: Putri Sembiring | C12: putrisembiring132@yahoo.com | D12: 89578248963 | E12: Balikpapan | F12: Kalimantan Timur | G12: 45609 | H12: Female | I12: 18-24
A13: CUST0012 | B13: Shinta Ramadhan | C13: shintaramadhan922@gmail.com | D13: 85871331509 | E13: Balikpapan | F13: Kalimantan Timur | G13: 44668 | H13: Female | I13: 25-34
... A15: CUST0014 | B15: Hana Halim | C15: hanahalim97@yahoo.com | D15: 81365667010 | E15: Depok | F15: Jawa Barat | G15: 44891 | H15: Female | I15: 35-44
A16: CUST0015 | B16: Sari Permata | C16: saripermata460@gmail.com | E16: Medan | F16: Sumatera Utara | G16: 44300 | H16: Female | I16: 35-44
A17: CUST0016 | B17: Siti Nugroho | C17: sitinugroho171@yahoo.com | D17: 85677360260 | E17: Depok | F17: Jawa Barat | G17: 44740 | H17: Female | I17: 45+
A18: CUST0017 | B18: Wahyu Tanjung | C18: wahyutanjung678@gmail.com | D18: 89672343098 | E18: Surabaya | F18: Jawa Timur | G18: 44839 | H18: Male | I18: 18-24
A19: CUST0018 | B19: Dion Hutapea | C19: dionhutapea59@yahoo.com | D19: 85812191361 | E19: Manado | F19: Sulawesi Utara | G19: 44701 | H19: Male | I19: 25-34
A20: CUST0019 | B20: Rina Halim | C20: rinahalim579@gmail.com | D20: 85854353462 | E20: Malang | F20: Jawa Timur | G20: 45133 | H20: Female | I20: 25-34
A21: CUST0020 | B21: Joko Saputra | C21: jokosaputra637@gmail.com | D21: 87811838425 | E21: Bandung | F21: Jawa Barat | G21: 44697 | H21: Male | I21: 25-34
A22: CUST0021 | B22: Mawar Yulianti | C22: mawaryulianti827@gmail.com | D22: 89580841241 | E22: Medan | F22: Sumatera Utara | G22: 45330 | H22: Female | I22: 18-24
A23: CUST0022 | B23: Fitri Hasanah | C23: fitrihasanah704@yahoo.com | D23: 89548740164 | E23: Surabaya | F23: Jawa Timur | G23: 44204 | H23: Female | I23: 25-34
A24: CUST0023 | B24: Citra Maharani | C24: citramaharani565@gmail.com | D24: 89668011280 | E24: Tangerang | F24: Banten | G24: 45389 | H24: Female | I24: 25-34
A25: CUST0024 | B25: Sri Yulianti | C25: sriyulianti921@outlook.com | D25: 81253315869 | E25: Makassar | F25: Sulawesi Selatan | G25: 44681 | H25: Female | I25: 35-44
A26: CUST0025 | B26: Adi Halim | C26: adihalim184@gmail.com | D26: 89656342160 | E26: Pekanbaru | F26: Riau | G26: 44652 | H26: Male | I26: 18-24
A27: CUST0026 | B27: Nanda Yulianti | C27: nandayulianti229@yahoo.com | D27: 81236541458 | E27: Depok | F27: Jawa Barat | G27: 45588 | H27: Male | I27: 45+
A28: CUST0027 | B28: Dewi Kurniawan | C28: dewikurniawan183@outlook.com | D28: 87840196556 | E28: Pontianak | F28: Kalimantan Barat | G28: 45244 | H28: Female | I28: 18-24
... A80: CUST0079 | B80: Wulan Rahmawati | C80: wulanrahmawati649@gmail.com | D80: 87885698478 | E80: Pontianak | F80: Kalimantan Barat | G80: 45078 | H80: Female | I80: 18-24
A81: CUST0080 | B81: Maulana Tarigan | C81: maulanatarigan441@yahoo.com | E81: Bogor | F81: Jawa Barat | G81: 44837 | H81: Male | I81: 35-44
A82: CUST0081 | B82: Indah Pohan | C82: indahpohan94@gmail.com | D82: 81316152809 | E82: Balikpapan | F82: Kalimantan Timur | G82: 45347 | H82: Female | I82: 25-34
A83: CUST0082 | B83: Bella Tanjung | C83: bellatanjung992@gmail.com | D83: 85294519832 | E83: Pekanbaru | F83: Riau | G83: 44656 | H83: Female | I83: 35-44
A84: CUST0083 | B84: Melati Ramadhan | C84: melatiramadhan781@gmail.com | D84: 85293689980 | E84: Pontianak | F84: Kalimantan Barat | G84: 45544 | H84: Female | I84: 35-44
A85: CUST0084 | B85: Mira Rahmawati | C85: mirarahmawati944@outlook.com | D85: 85350229612 | E85: Jakarta | F85: DKI Jakarta | G85: 44384 | H85: Female | I85: 35-44
A86: CUST0085 | B86: Mega Simbolon | C86: megasimbolon162@outlook.com | D86: 85345991022 | E86: Pontianak | F86: Kalimantan Barat | G86: 44298 | H86: Female | I86: 35-44
A87: CUST0086 | B87: Shinta Tanjung | C87: shintatanjung622@gmail.com | D87: 85764381561 | E87: Malang | F87: Jawa Timur | G87: 45585 | H87: Female | I87: 35-44
A88: CUST0087 | B88: Shinta Yulianti | C88: shintayulianti226@gmail.com | D88: 85690034324 | E88: Malang | F88: Jawa Timur | G88: 44868 | H88: Female | I88: 18-24
A89: CUST0088 | B89: Lia Wardani | C89: liawardani390@yahoo.com | D89: 85838851606 | E89: Jakarta | F89: DKI Jakarta | G89: 45138 | H89: Female | I89: 45+
A90: CUST0089 | B90: Irfan Tanjung | C90: irfantanjung415@gmail.com | D90: 89664160529 | E90: Padang | F90: Sumatera Barat | G90: 45609 | H90: Male | I90: 45+
A91: CUST0090 | B91: Lina Suryadi | C91: linasuryadi604@gmail.com | D91: 85681645352 | E91: Bandung | F91: Jawa Barat | G91: 45242 | H91: Female | I91: 25-34
A92: CUST0091 | B92: Sari Aprilia | C92: sariaprilia745@outlook.com | D92: 89523124329 | E92: Makassar | F92: Sulawesi Selatan | G92: 45539 | H92: Female | I92: 18-24
...

Sheet raw_reviews
A1: review_id | B1: order_id | C1: product_id | D1: customer_id | E1: rating | F1: review_text | G1: review_date | H1: helpful_count
A2: REV00001 | B2: ORD000131 | C2: PRD269 | D2: CUST0714 | E2: 3 | F2: Bahan premium, jahitan kuat. | G2: 45338 | H2: 0
A3: REV00002 | B3: ORD001162 | C3: PRD105 | D3: CUST0586 | E3: 2 | F3: Bagus banget, packaging juga aman. | G3: 45681 | H3: 0
A4: REV00003 | B4: ORD001172 | C4: PRD053 | D4: CUST0164 | E4: 5 | F4: Modelnya keren, fit di badan. | G4: 45553 | H4: 18
A5: REV00004 | B5: ORD002879 | C5: PRD265 | D5: CUST0179 | E5: 4 | F5: Kualitas oke untuk harga segini. | G5: 45367 | H5: 0
A6: REV00005 | B6: ORD001303 | C6: PRD252 | D6: CUST0606 | E6: 3 | F6: Produk sampai dengan cepat, sesuai ekspektasi. | G6: 45317 | H6: 46
A7: REV00006 | B7: ORD002340 | C7: PRD028 | D7: CUST0465 | E7: 5 | F7: Mantap, langganan terus dari sini. | G7: 45287 | H7: 0
A8: REV00007 | B8: ORD002140 | C8: PRD096 | D8: CUST0616 | E8: 5 | F8: Sesuai deskripsi, akan beli lagi. | G8: 45319 | H8: 0
A9: REV00008 | B9: ORD002124 | C9: PRD023 | D9: CUST0030 | E9: 5 | F9: Wah ini sih murah meriah tapi berkualitas. | G9: 45446 | H9: 11
A10: REV00009 | B10: ORD002964 | C10: PRD181 | D10: CUST0479 | E10: 3 | F10: Produknya bagus tapi pengiriman lama. | G10: 45204 | H10: 0
A11: REV00010 | B11: ORD001442 | C11: PRD072 | D11: CUST0550 | E11: 3 | F11: Modelnya keren, fit di badan. | G11: 45239 | H11: 0
A12: REV00011 | B12: ORD002046 | C12: PRD254 | D12: CUST0488 | E12: 5 | G12: 45460 | H12: 0
A13: REV00012 | B13: ORD001842 | C13: PRD019 | D13: CUST0480 | E13: 4 | F13: Pengiriman cepat, packaging rapi. | G13: 45667 | H13: 6
A14: REV00013 | B14: ORD000293 | C14: PRD150 | D14: CUST0135 | E14: 5 | F14: Suka banget, repeat order pasti. | G14: 44677 | H14: 9
A15: REV00014 | B15: ORD001301 | C15: PRD210 | D15: CUST0141 | E15: 5 | F15: Ukuran agak kekecilan, tapi bahan oke. | G15: 44717 | H15: 11
A16: REV00015 | B16: ORD001293 | C16: PRD270 | D16: CUST0531 | E16: 4 | F16: Pengiriman cepat, packaging rapi. | G16: 44918 | H16: 9
A17: REV00016 | B17: ORD000867 | C17: PRD259 | D17: CUST0270 | E17: 5 | F17: Bagus banget, packaging juga aman. | G17: 45132 | H17: 31
A18: REV00017 | B18: ORD001287 | C18: PRD280 | D18: CUST0048 | E18: 5 | F18: Produk original, terima kasih seller. | G18: 45593 | H18: 0
A19: REV00018 | B19: ORD000965 | C19: PRD102 | D19: CUST0758 | E19: 3 | F19: Jahitannya kurang rapi, tapi masih bisa dipake. | G19: 45595 | H19: 6
A20: REV00019 | B20: ORD000890 | C20: PRD195 | D20: CUST0778 | E20: 5 | F20: Awalnya ragu, ternyata kualitasnya oke. | G20: 45401 | H20: 0
A21: REV00020 | B21: ORD002400 | C21: PRD172 | D21: CUST0417 | E21: 5 | F21: Agak mengecewakan, bahannya panas. | G21: 45210 | H21: 0
A22: REV00021 | B22: ORD002369 | C22: PRD196 | D22: CUST0259 | E22: 5 | F22: Suka banget, repeat order pasti. | G22: 45522 | H22: 3
A23: REV00022 | B23: ORD001470 | C23: PRD297 | D23: CUST0376 | E23: 5 | F23: Warna agak beda dari foto. | G23: 44927 | H23: 0
A24: REV00023 | B24: ORD002158 | C24: PRD213 | D24: CUST0682 | E24: 4 | G24: 45157 | H24: 10
A25: REV00024 | B25: ORD000417 | C25: PRD013 | D25: CUST0527 | E25: 4 | F25: Produk sampai dengan cepat, sesuai ekspektasi. | G25: 45363 | H25: 4
A26: REV00025 | B26: ORD002694 | C26: PRD298 | D26: CUST0293 | E26: 5 | F26: Tidak sesuai ekspektasi, kurang puas. | G26: 45103 | H26: 0
A27: REV00026 | B27: ORD001044 | C27: PRD181 | D27: CUST0226 | E27: 5 | F27: Cocok buat hangout, modelnya kekinian. | G27: 45272 | H27: 10
A28: REV00027 | B28: ORD000043 | C28: PRD009 | D28: CUST0575 | E28: 4 | G28: 45388 | H28: 2
A29: REV00028 | B29: ORD002050 | C29: PRD005 | D29: CUST0521 | E29: 3 | F29: Bahannya enak banget, jahitan rapi. Recommended! | G29: 45675 | H29: 0
A30: REV00029 | B30: ORD000334 | C30: PRD001 | D30: CUST0148 | E30: 5 | F30: Kainnya tipis, agak kecewa. | G30: 44637 | H30: 0
A31: REV00030 | B31: ORD002146 | C31: PRD026 | D31: CUST0354 | E31: 5 | F31: Modelnya simple, gampang di-mix and match. | G31: 44905 | H31: 0
A32: REV00031 | B32: ORD001633 | C32: PRD156 | D32: CUST0573 | E32: 5 | F32: Warna agak beda dari foto. | G32: 45396 | H32: 9
A33: REV00032 | B33: ORD001736 | C33: PRD219 | D33: CUST0160 | E33: 5 | F33: Bahan premium, jahitan kuat. | G33: 44922 | H33: 10
A34: REV00033 | B34: ORD000016 | C34: PRD052 | D34: CUST0441 | E34: 4 | F34: Bagus banget, packaging juga aman. | G34: 45424 | H34: 3
A35: REV00034 | B35: ORD000216 | C35: PRD060 | D35: CUST0177 | E35: 5 | F35: Awalnya ragu, ternyata kualitasnya oke. | G35: 45566 | H35: 0
A36: REV00035 | B36: ORD002501 | C36: PRD113 | D36: CUST0565 | E36: 3 | F36: Kualitas oke untuk harga segini. | G36: 44677 | H36: 0
A37: REV00036 | B37: ORD002750 | C37: PRD298 | D37: CUST0096 | E37: 4 | F37: Bagus banget, packaging juga aman. | G37: 45418 | H37: 6
A38: REV00037 | B38: ORD001607 | C38: PRD275 | D38: CUST0143 | E38: 5 | F38: Bahannya enak banget, jahitan rapi. Recommended! | G38: 44647 | H38: 27
A39: REV00038 | B39: ORD000825 | C39: PRD276 | D39: CUST0218 | E39: 3 | F39: Produk original, terima kasih seller. | G39: 45720 | H39: 0
A40: REV00039 | B40: ORD001079 | C40: PRD195 | D40: CUST0057 | E40: 5 | F40: Bahan premium, jahitan kuat. | G40: 45053 | H40: 0
...

Sheet raw_products
A1: product_id | B1: name | C1: category | D1: sub_category | E1: price_idr | F1: stock | G1: brand | H1: material | I1: avg_rating
A2: PRD001 | B2: Dress Bodycon Pesona Indo | C2: dress | D2: Atasan Wanita | E2: 599000 | F2: 0 | G2: Pesona Indo | H2: Linen | I2: 5
A3: PRD002 | B3: Kaos Oversize BajuKita | C3: T-Shirt | D3: Atasan Pria | E3: 329000 | F3: 239 | G3: BajuKita | H3: Cotton 100% | I3: 3.7
A4: PRD003 | B4: Dress Maxi Polos Senja Wear | C4: dress | D4: Atasan Wanita | E4: 349000 | F4: 80 | G4: Senja Wear | H4: Cotton-Polyester | I4: 4.7
A5: PRD004 | B5: Ikat Pinggang Kulit Cendana Co | C5: Accessories | D5: Aksesoris | E5: 199000 | F5: 309 | G5: Cendana Co | H5: Denim | I5: 4.6
A6: PRD005 | B6: Dress Bodycon Senja Wear | C6: dress | D6: Atasan Wanita | E6: 599000 | F6: 192 | G6: Senja Wear | H6: Polyester | I6: 3.5
A7: PRD006 | B7: Celana Kulot Tropika Style | C7: Pants | D7: Bawahan Wanita | E7: 119000 | F7: 193 | G7: Tropika Style | H7: Polyester | I7: 4.9
A8: PRD007 | B8: T-Shirt Graphic Cendana Co | C8: Kaos | D8: Atasan Wanita | E8: 119000 | F8: 1 | G8: Cendana Co | H8: Rayon | I8: 4.9
A9: PRD008 | B9: Jaket Bomber Senja Wear | C9: Jaket | D9: Outwear | E9: 549000 | F9: 222 | G9: Senja Wear | H9: Denim | I9: 3.9
A10: PRD009 | B10: Kaos Striped Riang Apparel | C10: T-Shirt | D10: Atasan Pria | E10: 499000 | F10: 41 | G10: Riang Apparel | H10: Twill | I10: 4.7
A11: PRD010 | B11: Kaos Raglan BajuKita | C11: kaos | D11: Atasan Pria | E11: 99000 | F11: 414 | G11: BajuKita | H11: Cotton Combed 30s | I11: 3.6
A12: PRD011 | B12: Topi Baseball Cendana Co | C12: Aksesoris | D12: Aksesoris | E12: 149000 | F12: 370 | G12: Cendana Co | H12: Rayon | I12: 4.8
A13: PRD012 | B13: Kemeja Batik NusaBrand | C13: Shirt | D13: Atasan Wanita | E13: 599000 | F13: 26 | G13: NusaBrand | H13: Twill | I13: 3.7
... A25: PRD024 | B25: Kemeja Linen Tropika Style | C25: Shirt | D25: Atasan Pria | E25: 149000 | F25: 37 | G25: Tropika Style | H25: Polyester | I25: 4.9
A26: PRD025 | B26: Jacket Denim Kanvas Lokal | C26: Jaket | D26: Outwear | E26: 59000 | F26: 272 | G26: Kanvas Lokal | I26: 4.1
A27: PRD026 | B27: Dress Mini Casual BajuKita | C27: Dress | D27: Atasan Wanita | E27: 179000 | F27: 20 | G27: BajuKita | H27: Linen | I27: 4.2
A28: PRD027 | B28: Dompet Kulit Cendana Co | C28: Aksesoris | D28: Aksesoris | E28: 229000 | F28: 1 | G28: Cendana Co | H28: Katun Bambu | I28: 4.3
A29: PRD028 | B29: Dress Bodycon Tropika Style | C29: Dress | D29: Atasan Wanita | E29: 299000 | F29: 112 | G29: Tropika Style | H29: Rayon | I29: 4.6
A30: PRD029 | B30: Shirt Slim Fit Tropika Style | C30: kemeja | D30: Atasan Wanita | E30: 499000 | F30: 26 | G30: Tropika Style | H30: Drill | I30: 3.5
A31: PRD030 | B31: Jaket Hoodie Kanvas Lokal | C31: Jaket | D31: Outwear | E31: 199000 | F31: 403 | G31: Kanvas Lokal | H31: Linen | I31: 3.7
A32: PRD031 | B32: Shirt Slim Fit Tropika Style | C32: Kemeja | D32: Atasan Pria | E32: 69000 | F32: 148 | G32: Tropika Style | H32: Denim | I32: 4
A33: PRD032 | B33: Ikat Pinggang Kulit Tropika Style | C33: Accessories | D33: Aksesoris | E33: 99000 | F33: 464 | G33: Tropika Style | H33: Katun Bambu | I33: 4.7
A34: PRD033 | B34: Celana Chino BajuKita | C34: Celana | D34: Bawahan Wanita | E34: 199000 | F34: 197 | G34: BajuKita | H34: Katun Bambu | I34: 3.5
A35: PRD034 | B35: Topi Baseball Senja Wear | C35: Accessories | D35: Aksesoris | E35: 279000 | F35: 79 | G35: Senja Wear | H35: Katun Bambu | I35: 4.6
A36: PRD035 | B36: Jacket Denim Tropika Style | C36: Jacket | D36: Outwear | E36: 399000 | F36: 49 | G36: Tropika Style | H36: Rayon | I36: 4.9
A37: PRD036 | B37: Syal Rajut Pesona Indo | C37: Accessories | D37: Aksesoris | E37: 299000 | F37: 28 | G37: Pesona Indo | H37: Cotton Combed 30s | I37: 4.8
A38: PRD037 | B38: Dress A-Line Kanvas Lokal | C38: dress | D38: Atasan Wanita | E38: 149000 | F38: 136 | G38: Kanvas Lokal | H38: Cotton 100% | I38: 4.3
... A68: PRD067 | B68: Jaket Parasut Riang Apparel | C68: Jacket | D68: Outwear | E68: 549000 | F68: 11 | G68: Riang Apparel | H68: Cotton-Polyester | I68: 3.5
A69: PRD068 | B69: T-Shirt Graphic Ratu Mode | C69: kaos | D69: Atasan Pria | E69: 129000 | F69: 121 | G69: Ratu Mode | I69: 4.2
A70: PRD069 | B70: Jacket Coach Ratu Mode | C70: Jaket | D70: Outwear | E70: 229000 | F70: 58 | G70: Ratu Mode | H70: Rayon | I70: 4.3
A71: PRD070 | B71: Celana Cargo Pesona Indo | C71: Celana | D71: Bawahan Pria | E71: 349000 | F71: 112 | G71: Pesona Indo | H71: Polyester | I71: 4.5
A72: PRD071 | B72: Dompet Kulit Riang Apparel | C72: Aksesoris | D72: Aksesoris | E72: 99000 | F72: 3 | G72: Riang Apparel | H72: Linen | I72: 4.6
A73: PRD072 | B73: Kaos Polos Basic Ratu Mode | C73: Kaos | D73: Atasan Wanita | E73: 129000 | F73: 199 | G73: Ratu Mode | H73: Cotton Combed 30s | I73: 4.3
A74: PRD073 | B74: Kaos Oversize Riang Apparel | C74: kaos | D74: Atasan Pria | E74: 79000 | F74: 29 | G74: Riang Apparel | H74: Twill | I74: 4.4
A75: PRD074 | B75: Jaket Varsity NusaBrand | C75: Jacket | D75: Outwear | E75: 449000 | F75: 78 | G75: NusaBrand | H75: Linen | I75: 4.4
A76: PRD075 | B76: Ikat Pinggang Kulit Tropika Style | C76: Accessories | D76: Aksesoris | E76: 499000 | F76: 18 | G76: Tropika Style | H76: Katun Bambu | I76: 4.3
A77: PRD076 | B77: Syal Rajut Ratu Mode | C77: Accessories | D77: Aksesoris | E77: 199000 | F77: 18 | G77: Ratu Mode | H77: Katun Bambu | I77: 3.7
A78: PRD077 | B78: Shirt Slim Fit Cendana Co | C78: kemeja | D78: Atasan Pria | E78: 329000 | F78: 32 | G78: Cendana Co | H78: Cotton-Polyester | I78: 4.5
A79: PRD078 | B79: Kaos Striped Cendana Co | C79: kaos | D79: Atasan Wanita | E79: 99000 | F79: 13 | G79: Cendana Co | H79: Twill | I79: 4
A80: PRD079 | B80: Jacket Coach Senja Wear | C80: Jacket | D80: Outwear | E80: 499000 | F80: 14 | G80: Senja Wear | H80: Linen | I80: 4.6
...

Sheet raw_orders
A1: order_id | B1: customer_id | C1: order_date | D1: total_amount_idr | E1: shipping_city | F1: shipping_province | G1: shipping_cost_idr | H1: payment_method | I1: order_status | J1: promo_code | K1: discount_amount_idr | L1: courier
A2: ORD000001 | B2: CUST0474 | C2: 45008 | D2: 1951591 | E2: Banjarmasin | F2: Kalimantan Selatan | G2: 32066 | H2: Transfer Bank | I2: shipped | J2: WEEKEND25 | K2: 44409 | L2: JNE
A3: ORD000002 | B3: CUST0478 | C3: 45714 | D3: 507000 | E3: Palembang | F3: Sumatera Selatan | G3: 33769 | H3: Kartu Kredit | I3: delivered | J3: TANPA PROMO | L3: JNE
A4: ORD000003 | B4: CUST0306 | C4: 44755 | D4: 199000 | E4: Tangerang | F4: Banten | G4: 12060 | H4: Transfer Bank | I4: delivered | J4: TANPA PROMO | L4: SiCepat
A5: ORD000004 | B5: CUST0777 | C5: 45622 | D5: 119000 | E5: Medan | F5: Sumatera Utara | G5: 29005 | H5: Transfer Bank | I5: cancelled | J5: TANPA PROMO | L5: Anteraja
A6: ORD000005 | B6: CUST0210 | C6: 45138 | D6: 358000 | E6: Bandung | F6: Jawa Barat | G6: 11192 | H6: Kartu Kredit | I6: cancelled | J6: TANPA PROMO | L6: JNE
A7: ORD000006 | B7: CUST0444 | C7: 44693 | D7: 349000 | E7: Balikpapan | F7: Kalimantan Timur | G7: 37816 | H7: Transfer Bank | I7: returned | J7: TANPA PROMO | L7: SiCepat
A8: ORD000007 | B8: CUST0170 | C8: 44597 | D8: 407000 | E8: Bekasi | F8: Jawa Barat | G8: 13600 | H8: Transfer Bank | I8: delivered | J8: TANPA PROMO | L8: JNE
A9: ORD000008 | B9: CUST0637 | C9: 45079 | D9: 954364 | E9: Manado | F9: Sulawesi Utara | G9: 34020 | H9: Kartu Kredit | I9: processing | J9: WEEKEND25 | K9: 31636 | L9: J&T
A10: ORD000009 | B10: CUST0677 | C10: 45650 | D10: 230288 | E10: Surabaya | F10: Jawa Timur | G10: 13179 | H10: Transfer Bank | I10: cancelled | J10: HARBOLNAS22 | K10: 18712 | L10: JNE
A11: ORD000010 | B11: CUST0200 | C11: 45030 | D11: 264669 | E11: Pontianak | F11: Kalimantan Barat | G11: 30484 | H11: GoPay | I11: delivered | J11: HARI BELANJA | K11: 14331 | L11: Pos Indonesia
A12: ORD000011 | B12: CUST0225 | C12: 45015 | D12: 226000 | E12: Bekasi | F12: Jawa Barat | G12: 9935 | H12: Transfer Bank | I12: delivered | J12: TANPA PROMO | L12: Anteraja
A13: ORD000012 | B13: CUST0760 | C13: 45241 | D13: 251162 | E13: Balikpapan | F13: Kalimantan Timur | G13: 40940 | H13: OVO | I13: shipped | J13: HARI BELANJA | K13: 27838 | L13: J&T
A14: ORD000013 | B14: CUST0337 | C14: 45704 | D14: 199000 | E14: Depok | F14: Jawa Barat | G14: 9420 | H14: QRIS | I14: delivered | J14: TANPA PROMO | L14: Anteraja
A15: ORD000014 | B15: CUST0225 | C15: 45397 | D15: 334654 | E15: Medan | F15: Sumatera Utara | G15: 36425 | H15: GoPay | I15: delivered | J15: HARI BELANJA | K15: 14346 | L15: SiCepat
A16: ORD000015 | B16: CUST0794 | C16: 44940 | D16: 2537438 | E16: Pekanbaru | F16: Riau | G16: 29080 | H16: Transfer Bank | I16: delivered | J16: NEWUSER | K16: 36562 | L16: JNE
A17: ORD000016 | B17: CUST0441 | C17: 45420 | D17: 1746000 | E17: Manado | F17: Sulawesi Utara | G17: 34701 | H17: GoPay | I17: delivered | J17: TANPA PROMO | L17: J&T
A18: ORD000017 | B18: CUST0715 | C18: 45292 | D18: 355448 | E18: Semarang | F18: Jawa Tengah | G18: 12267 | H18: Transfer Bank | I18: returned | J18: RAMADAN23 | K18: 12552 | L18: J&T
A19: ORD000018 | B19: CUST0597 | C19: 44581 | D19: 119000 | E19: Bogor | F19: Jawa Barat | G19: 11574 | H19: Kartu Kredit | I19: cancelled | J19: TANPA PROMO | L19: SiCepat
A20: ORD000019 | B20: CUST0539 | C20: 44844 | D20: 247331 | E20: Balikpapan | F20: Kalimantan Timur | G20: 37574 | H20: OVO | I20: delivered | J20: FLASHSALE | K20: 20669 | L20: SiCepat
A21: ORD000020 | B21: CUST0712 | C21: 45150 | D21: 377322 | E21: Malang | F21: Jawa Timur | G21: 16405 | H21: OVO | I21: processing | J21: RAMADAN23 | K21: 19678 | L21: J&T
A22: ORD000021 | B22: CUST0111 | C22: 45662 | D22: 748000 | E22: Pontianak | F22: Kalimantan Barat | G22: 32628 | H22: Kartu Kredit | I22: shipped | J22: TANPA PROMO | L22: J&T
A23: ORD000022 | B23: CUST0566 | C23: 45442 | D23: 279000 | E23: Malang | F23: Jawa Timur | G23: 21336 | H23: GoPay | I23: delivered | J23: TANPA PROMO | L23: JNE
A24: ORD000023 | B24: CUST0259 | C24: 45153 | D24: 625000 | E24: Banjarmasin | F24: Kalimantan Selatan | G24: 34512 | H24: Kartu Kredit | I24: cancelled | J24: TANPA PROMO | L24: J&T
A25: ORD000024 | B25: CUST0189 | C25: 44651 | D25: 744000 | E25: Tangerang | F25: Banten | G25: 9763 | H25: GoPay | I25: returned | J25: TANPA PROMO | L25: JNE
A26: ORD000025 | B26: CUST0790 | C26: 44735 | D26: 288000 | E26: Balikpapan | F26: Kalimantan Timur | G26: 40074 | H26: GoPay | I26: delivered | J26: TANPA PROMO | L26: J&T
A27: ORD000026 | B27: CUST0755 | C27: 45429 | D27: 549000 | E27: Tangerang | F27: Banten | G27: 13331 | H27: QRIS | I27: shipped | J27: TANPA PROMO | L27: SiCepat
A28: ORD000027 | B28: CUST0561 | C28: 45140 | D28: 1098000 | E28: Yogyakarta | F28: DI Yogyakarta | G28: 13146 | H28: GoPay | I28: shipped | J28: TANPA PROMO | L28: SiCepat
A29: ORD000028 | B29: CUST0624 | C29: 45470 | D29: 408558 | E29: Balikpapan | F29: Kalimantan Timur | G29: 37360 | H29: Transfer Bank | I29: cancelled | J29: NEWUSER | K29: 39442 | L29: Anteraja
A30: ORD000029 | B30: CUST0245 | C30: 45109 | D30: 298000 | E30: Denpasar | F30: Bali | G30: 28769 | H30: Kartu Kredit | I30: delivered | J30: TANPA PROMO | L30: J&T
A31: ORD000030 | B31: CUST0566 | C31: 44985 | D31: 329000 | E31: Malang | F31: Jawa Timur | G31: 17186 | H31: OVO | I31: delivered | J31: TANPA PROMO | L31: J&T
A32: ORD000031 | B32: CUST0492 | C32: 44650 | D32: 200075 | E32: Pekanbaru | F32: Riau | G32: 26230 | H32: Transfer Bank | I32: delivered | J32: RAMADAN23 | K32: 28925 | L32: JNE
A33: ORD000032 | B33: CUST0317 | C33: 45660 | D33: 624526 | E33: Medan | F33: Sumatera Utara | G33: 38976 | H33: QRIS | I33: returned | J33: HARI BELANJA | K33: 43474 | L33: JNE
A34: ORD000033 | B34: CUST0126 | C34: 45208 | D34: 79000 | E34: Depok | F34: Jawa Barat | G34: 11918 | H34: Kartu Kredit | I34: delivered | J34: TANPA PROMO | L34: J&T
A35: ORD000034 | B35: CUST0636 | C35: 45325 | D35: 279000 | E35: Yogyakarta | F35: DI Yogyakarta | G35: 15802 | H35: Transfer Bank | I35: processing | J35: TANPA PROMO | L35: J&T
A36: ORD000035 | B36: CUST0775 | C36: 45194 | D36: 896000 | E36: Semarang | F36: Jawa Tengah | G36: 13372 | H36: Transfer Bank | I36: shipped | J36: TANPA PROMO | L36: SiCepat
A37: ORD000036 | B37: CUST0571 | C37: 45484 | D37: 548000 | E37: Manado | F37: Sulawesi Utara | G37: 35262 | H37: Kartu Kredit | I37: delivered | J37: TANPA PROMO | L37: JNE
A38: ORD000037 | B38: CUST0323 | C38: 45327 | D38: 218221 | E38: Pontianak | F38: Kalimantan Barat | G38: 36528 | H38: OVO | I38: delivered | J38: HARBOLNAS22 | K38: 30779 | L38: JNE
A39: ORD000038 | B39: CUST0252 | C39: 45117 | D39: 798000 | E39: Balikpapan | F39: Kalimantan Timur | G39: 31746 | H39: Transfer Bank | I39: delivered | J39: TANPA PROMO | L39: Pos Indonesia
A40: ORD000039 | B40: CUST0288 | C40: 45110 | D40: 329000 | E40: Tangerang | F40: Banten | G40: 9615 | H40: GoPay | I40: shipped | J40: TANPA PROMO | L40: J&T
...

Sheet raw_order_items
A1: item_id | B1: order_id | C1: product_id | D1: quantity | E1: unit_price_idr | F1: subtotal_idr
A2: ITM000001 | B2: ORD000001 | C2: PRD070 | D2: 1 | E2: 349000 | F2: 349000
A3: ITM000002 | B3: ORD000001 | C3: PRD001 | D3: 2 | E3: 599000 | F3: 1198000
A4: ITM000003 | B4: ORD000001 | C4: PRD148 | D4: 1 | E4: 449000 | F4: 449000
A5: ITM000004 | B5: ORD000002 | C5: PRD086 | D5: 1 | E5: 329000 | F5: 329000
A6: ITM000005 | B6: ORD000002 | C6: PRD258 | D6: 1 | E6: 129000 | F6: 129000
A7: ITM000006 | B7: ORD000002 | C7: PRD256 | D7: 1 | E7: 49000 | F7: 49000
A8: ITM000007 | B8: ORD000003 | C8: PRD076 | D8: 1 | E8: 199000 | F8: 199000
A9: ITM000008 | B9: ORD000004 | C9: PRD205 | D9: 1 | E9: 119000 | F9: 119000
A10: ITM000009 | B10: ORD000005 | C10: PRD239 | D10: 2 | E10: 179000 | F10: 358000
A11: ITM000010 | B11: ORD000006 | C11: PRD170 | D11: 1 | E11: 349000 | F11: 349000
A12: ITM000011 | B12: ORD000007 | C12: PRD013 | D12: 1 | E12: 149000 | F12: 149000
A13: ITM000012 | B13: ORD000007 | C13: PRD230 | D13: 2 | E13: 129000 | F13: 258000
... A4987: ITM004986 | B4987: ORD003000 | C4987: PRD117 | D4987: 1 | E4987: 49000 | F4987: 49000

Sheet clean_products
A1: product_id | B1: name | C1: category | D1: sub_category | E1: price_idr | F1: stock | G1: brand | H1: material | I1: avg_rating
A2: PRD001 | B2: Dress Bodycon Pesona Indo | C2: dress | D2: Atasan Wanita | E2: 599000 | F2: 0 | G2: Pesona Indo | H2: Linen | I2: 5
A3: PRD002 | B3: T-Shirt Oversize BajuKita | C3: T-Shirt | D3: Atasan Pria | E3: 329000 | F3: 239 | G3: BajuKita | H3: Cotton 100% | I3: 3.7
A4: PRD003 | B4: Dress Maxi Polos Senja Wear | C4: dress | D4: Atasan Wanita | E4: 349000 | F4: 80 | G4: Senja Wear | H4: Cotton-Polyester | I4: 4.7
A5: PRD004 | B5: Ikat Pinggang Kulit Cendana Co | C5: Accessories | D5: Accessories | E5: 199000 | F5: 309 | G5: Cendana Co | H5: Denim | I5: 4.6
A6: PRD005 | B6: Dress Bodycon Senja Wear | C6: dress | D6: Atasan Wanita | E6: 599000 | F6: 192 | G6: Senja Wear | H6: Polyester | I6: 3.5
A7: PRD006 | B7: Pants Kulot Tropika Style | C7: Pants | D7: Bawahan Wanita | E7: 119000 | F7: 193 | G7: Tropika Style | H7: Polyester | I7: 4.9
A8: PRD007 | B8: T-Shirt Graphic Cendana Co | C8: T-Shirt | D8: Atasan Wanita | E8: 119000 | F8: 1 | G8: Cendana Co | H8: Rayon | I8: 4.9
A9: PRD008 | B9: Jacket Bomber Senja Wear | C9: Jacket | D9: Outwear | E9: 549000 | F9: 222 | G9: Senja Wear | H9: Denim | I9: 3.9
A10: PRD009 | B10: T-Shirt Striped Riang Apparel | C10: T-Shirt | D10: Atasan Pria | E10: 499000 | F10: 41 | G10: Riang Apparel | H10: Twill | I10: 4.7
A11: PRD010 | B11: T-Shirt Raglan BajuKita | C11: T-Shirt | D11: Atasan Pria | E11: 99000 | F11: 414 | G11: BajuKita | H11: Cotton Combed 30s | I11: 3.6
A12: PRD011 | B12: Topi Baseball Cendana Co | C12: Accessories | D12: Accessories | E12: 149000 | F12: 370 | G12: Cendana Co | H12: Rayon | I12: 4.8
A13: PRD012 | B13: Kemeja Batik NusaBrand | C13: T-Shirt | D13: Atasan Wanita | E13: 599000 | F13: 26 | G13: NusaBrand | H13: Twill | I13: 3.7
... A25: PRD024 | B25: Kemeja Linen Tropika Style | C25: T-Shirt | D25: Atasan Pria | E25: 149000 | F25: 37 | G25: Tropika Style | H25: Polyester | I25: 4.9
A26: PRD025 | B26: Jacket Denim Kanvas Lokal | C26: Jacket | D26: Outwear | E26: 59000 | F26: 272 | G26: Kanvas Lokal | I26: 4.1
A27: PRD026 | B27: Dress Mini Casual BajuKita | C27: Dress | D27: Atasan Wanita | E27: 179000 | F27: 20 | G27: BajuKita | H27: Linen | I27: 4.2
A28: PRD027 | B28: Dompet Kulit Cendana Co | C28: Accessories | D28: Accessories | E28: 229000 | F28: 1 | G28: Cendana Co | H28: Katun Bambu | I28: 4.3
A29: PRD028 | B29: Dress Bodycon Tropika Style | C29: Dress | D29: Atasan Wanita | E29: 299000 | F29: 112 | G29: Tropika Style | H29: Rayon | I29: 4.6
A30: PRD029 | B30: T-Shirt Slim Fit Tropika Style | C30: kemeja | D30: Atasan Wanita | E30: 499000 | F30: 26 | G30: Tropika Style | H30: Drill | I30: 3.5
A31: PRD030 | B31: Jacket Hoodie Kanvas Lokal | C31: Jacket | D31: Outwear | E31: 199000 | F31: 403 | G31: Kanvas Lokal | H31: Linen | I31: 3.7
A32: PRD031 | B32: T-Shirt Slim Fit Tropika Style | C32: Kemeja | D32: Atasan Pria | E32: 69000 | F32: 148 | G32: Tropika Style | H32: Denim | I32: 4
A33: PRD032 | B33: Ikat Pinggang Kulit Tropika Style | C33: Accessories | D33: Accessories | E33: 99000 | F33: 464 | G33: Tropika Style | H33: Katun Bambu | I33: 4.7
A34: PRD033 | B34: Pants Chino BajuKita | C34: Pants | D34: Bawahan Wanita | E34: 199000 | F34: 197 | G34: BajuKita | H34: Katun Bambu | I34: 3.5
A35: PRD034 | B35: Topi Baseball Senja Wear | C35: Accessories | D35: Accessories | E35: 279000 | F35: 79 | G35: Senja Wear | H35: Katun Bambu | I35: 4.6
A36: PRD035 | B36: Jacket Denim Tropika Style | C36: Jacket | D36: Outwear | E36: 399000 | F36: 49 | G36: Tropika Style | H36: Rayon | I36: 4.9
A37: PRD036 | B37: Syal Rajut Pesona Indo | C37: Accessories | D37: Accessories | E37: 299000 | F37: 28 | G37: Pesona Indo | H37: Cotton Combed 30s | I37: 4.8
A38: PRD037 | B38: Dress A-Line Kanvas Lokal | C38: dress | D38: Atasan Wanita | E38: 149000 | F38: 136 | G38: Kanvas Lokal | H38: Cotton 100% | I38: 4.3
... A68: PRD067 | B68: Jacket Parasut Riang Apparel | C68: Jacket | D68: Outwear | E68: 549000 | F68: 11 | G68: Riang Apparel | H68: Cotton-Polyester | I68: 3.5
A69: PRD068 | B69: T-Shirt Graphic Ratu Mode | C69: T-Shirt | D69: Atasan Pria | E69: 129000 | F69: 121 | G69: Ratu Mode | I69: 4.2
A70: PRD069 | B70: Jacket Coach Ratu Mode | C70: Jacket | D70: Outwear | E70: 229000 | F70: 58 | G70: Ratu Mode | H70: Rayon | I70: 4.3
A71: PRD070 | B71: Pants Cargo Pesona Indo | C71: Pants | D71: Bawahan Pria | E71: 349000 | F71: 112 | G71: Pesona Indo | H71: Polyester | I71: 4.5
A72: PRD071 | B72: Dompet Kulit Riang Apparel | C72: Accessories | D72: Accessories | E72: 99000 | F72: 3 | G72: Riang Apparel | H72: Linen | I72: 4.6
A73: PRD072 | B73: T-Shirt Polos Basic Ratu Mode | C73: T-Shirt | D73: Atasan Wanita | E73: 129000 | F73: 199 | G73: Ratu Mode | H73: Cotton Combed 30s | I73: 4.3
A74: PRD073 | B74: T-Shirt Oversize Riang Apparel | C74: T-Shirt | D74: Atasan Pria | E74: 79000 | F74: 29 | G74: Riang Apparel | H74: Twill | I74: 4.4
A75: PRD074 | B75: Jacket Varsity NusaBrand | C75: Jacket | D75: Outwear | E75: 449000 | F75: 78 | G75: NusaBrand | H75: Linen | I75: 4.4
A76: PRD075 | B76: Ikat Pinggang Kulit Tropika Style | C76: Accessories | D76: Accessories | E76: 499000 | F76: 18 | G76: Tropika Style | H76: Katun Bambu | I76: 4.3
A77: PRD076 | B77: Syal Rajut Ratu Mode | C77: Accessories | D77: Accessories | E77: 199000 | F77: 18 | G77: Ratu Mode | H77: Katun Bambu | I77: 3.7
A78: PRD077 | B78: T-Shirt Slim Fit Cendana Co | C78: kemeja | D78: Atasan Pria | E78: 329000 | F78: 32 | G78: Cendana Co | H78: Cotton-Polyester | I78: 4.5
A79: PRD078 | B79: T-Shirt Striped Cendana Co | C79: T-Shirt | D79: Atasan Wanita | E79: 99000 | F79: 13 | G79: Cendana Co | H79: Twill | I79: 4
A80: PRD079 | B80: Jacket Coach Senja Wear | C80: Jacket | D80: Outwear | E80: 499000 | F80: 14 | G80: Senja Wear | H80: Linen | I80: 4.6
...

Sheet working_table
A1: order_id | B1: order_date | C1: order_status | D1: shiping_city | E1: shiping_province | F1: promo_code | G1: product_id | H1: quantity | I1: unit_price_idr | J1: sub_total_idr | K1: product_name | L1: category | M1: brands
A2: ORD000001 | B2: =VLOOKUP(A2,orders[#All],3,0) -> 45008 | C2: =VLOOKUP($A2,orders[#All],9,0) -> shipped | D2: =VLOOKUP($A2,orders[#All],5,0) -> Banjarmasin | E2: =VLOOKUP($A2,orders[#All],6,0) -> Kalimantan Selatan | F2: =VLOOKUP($A2,orders[#All],10,0) -> WEEKEND25 | G2: PRD070 | H2: =VLOOKUP(working_table!G2,order_items[[#All],[product_id]:[subtotal_idr]],2,0) -> 1 | I2: =VLOOKUP(working_table!$G2,order_items[[#All],[product_id]:[subtotal_idr]],3,0) -> 349000 | J2: =VLOOKUP(working_table!$G2,order_items[[#All],[product_id]:[subtotal_idr]],4,0) -> 349000 | K2: =VLOOKUP($G2,products7[#All],2,0) -> Pants Cargo Pesona Indo | L2: =VLOOKUP($G2,products7[#All],3,0) -> Pants | M2: =VLOOKUP($G2,products7[#All],7,0) -> Pesona Indo
A3: ORD000001 | B3: =VLOOKUP(A3,orders[#All],3,0) -> 45008 | C3: =VLOOKUP($A3,orders[#All],9,0) -> shipped | D3: =VLOOKUP($A3,orders[#All],5,0) -> Banjarmasin | E3: =VLOOKUP($A3,orders[#All],6,0) -> Kalimantan Selatan | F3: =VLOOKUP($A3,orders[#All],10,0) -> WEEKEND25 | G3: PRD001 | H3: =VLOOKUP(working_table!G3,order_items[[#All],[product_id]:[subtotal_idr]],2,0) -> 2 | I3: =VLOOKUP(working_table!$G3,order_items[[#All],[product_id]:[subtotal_idr]],3,0) -> 599000 | J3: =VLOOKUP(working_table!$G3,order_items[[#All],[product_id]:[subtotal_idr]],4,0) -> 1198000 | K3: =VLOOKUP($G3,products7[#All],2,0) -> Dress Bodycon Pesona Indo | L3: =VLOOKUP($G3,products7[#All],3,0) -> dress | M3: =VLOOKUP($G3,products7[#All],7,0) -> Pesona Indo
A4: ORD000001 | B4: =VLOOKUP(A4,orders[#All],3,0) -> 45008 | C4: =VLOOKUP($A4,orders[#All],9,0) -> shipped | D4: =VLOOKUP($A4,orders[#All],5,0) -> Banjarmasin | E4: =VLOOKUP($A4,orders[#All],6,0) -> Kalimantan Selatan | F4: =VLOOKUP($A4,orders[#All],10,0) -> WEEKEND25 | G4: PRD148 | H4: =VLOOKUP(working_table!G4,order_items[[#All],[product_id]:[subtotal_idr]],2,0) -> 1 | I4: =VLOOKUP(working_table!$G4,order_items[[#All],[product_id]:[subtotal_idr]],3,0) -> 449000 | J4: =VLOOKUP(working_table!$G4,order_items[[#All],[product_id]:[subtotal_idr]],4,0) -> 449000 | K4: =VLOOKUP($G4,products7[#All],2,0) -> T-Shirt Striped Kanvas Lokal | L4: =VLOOKUP($G4,products7[#All],3,0) -> T-Shirt | M4: =VLOOKUP($G4,products7[#All],7,0) -> Kanvas Lokal
A5: ORD000002 | B5: =VLOOKUP(A5,orders[#All],3,0) -> 45714 | C5: =VLOOKUP($A5,orders[#All],9,0) -> delivered | D5: =VLOOKUP($A5,orders[#All],5,0) -> Palembang | E5: =VLOOKUP($A5,orders[#All],6,0) -> Sumatera Selatan | F5: =VLOOKUP($A5,orders[#All],10,0) -> TANPA PROMO | G5: PRD086 | H5: =VLOOKUP(working_table!G5,order_items[[#All],[product_id]:[subtotal_idr]],2,0) -> 1 | I5: =VLOOKUP(working_table!$G5,order_items[[#All],[product_id]:[subtotal_idr]],3,0) -> 329000 | J5: =VLOOKUP(working_table!$G5,order_items[[#All],[product_id]:[subtotal_idr]],4,0) -> 329000 | K5: =VLOOKUP($G5,products7[#All],2,0) -> Pants Jogger SandangIndo | L5: =VLOOKUP($G5,products7[#All],3,0) -> Pants | M5: =VLOOKUP($G5,products7[#All],7,0) -> SandangIndo
A6: ORD000002 | B6: =VLOOKUP(A6,orders[#All],3,0) -> 45714 | C6: =VLOOKUP($A6,orders[#All],9,0) -> delivered | D6: =VLOOKUP($A6,orders[#All],5,0) -> Palembang | E6: =VLOOKUP($A6,orders[#All],6,0) -> Sumatera Selatan | F6: =VLOOKUP($A6,orders[#All],10,0) -> TANPA PROMO | G6: PRD258 | H6: =VLOOKUP(working_table!G6,order_items[[#All],[product_id]:[subtotal_idr]],2,0) -> 1 | I6: =VLOOKUP(working_table!$G6,order_items[[#All],[product_id]:[subtotal_idr]],3,0) -> 129000 | J6: =VLOOKUP(working_table!$G6,order_items[[#All],[product_id]:[subtotal_idr]],4,0) -> 129000 | K6: =VLOOKUP($G6,products7[#All],2,0) -> Kacamata Hitam Kanvas Lokal | L6: =VLOOKUP($G6,products7[#All],3,0) -> Accessories | M6: =VLOOKUP($G6,products7[#All],7,0) -> Kanvas Lokal
A7: ORD000002 | B7: =VLOOKUP(A7,orders[#All],3,0) -> 45714 | C7: =VLOOKUP($A7,orders[#All],9,0) -> delivered | D7: =VLOOKUP($A7,orders[#All],5,0) -> Palembang | E7: =VLOOKUP($A7,orders[#All],6,0) -> Sumatera Selatan | F7: =VLOOKUP($A7,orders[#All],10,0) -> TANPA PROMO | G7: PRD256 | H7: =VLOOKUP(working_table!G7,order_items[[#All],[product_id]:[subtotal_idr]],2,0) -> 1 | I7: =VLOOKUP(working_table!$G7,order_items[[#All],[product_id]:[subtotal_idr]],3,0) -> 49000 | J7: =VLOOKUP(working_table!$G7,order_items[[#All],[product_id]:[subtotal_idr]],4,0) -> 49000 | K7: =VLOOKUP($G7,products7[#All],2,0) -> Dress Maxi Polos Kanvas Lokal | L7: =VLOOKUP($G7,products7[#All],3,0) -> Dress | M7: =VLOOKUP($G7,products7[#All],7,0) -> Kanvas Lokal
A8: ORD000003 | B8: =VLOOKUP(A8,orders[#All],3,0) -> 44755 | C8: =VLOOKUP($A8,orders[#All],9,0) -> delivered | D8: =VLOOKUP($A8,orders[#All],5,0) -> Tangerang | E8: =VLOOKUP($A8,orders[#All],6,0) -> Banten | F8: =VLOOKUP($A8,orders[#All],10,0) -> TANPA PROMO | G8: PRD076 | H8: =VLOOKUP(working_table!G8,order_items[[#All],[product_id]:[subtotal_idr]],2,0) -> 1 | I8: =VLOOKUP(working_table!$G8,order_items[[#All],[product_id]:[subtotal_idr]],3,0) -> 199000 | J8: =VLOOKUP(working_table!$G8,order_items[[#All],[product_id]:[subtotal_idr]],4,0) -> 199000 | K8: =VLOOKUP($G8,products7[#All],2,0) -> Syal Rajut Ratu Mode | L8: =VLOOKUP($G8,products7[#All],3,0) -> Accessories | M8: =VLOOKUP($G8,products7[#All],7,0) -> Ratu Mode
A9: ORD000004 | B9: =VLOOKUP(A9,orders[#All],3,0) -> 45622 | C9: =VLOOKUP($A9,orders[#All],9,0) -> cancelled | D9: =VLOOKUP($A9,orders[#All],5,0) -> Medan | E9: =VLOOKUP($A9,orders[#All],6,0) -> Sumatera Utara | F9: =VLOOKUP($A9,orders[#All],10,0) -> TANPA PROMO | G9: PRD205 | H9: =VLOOKUP(working_table!G9,order_items[[#All],[product_id]:[subtotal_idr]],2,0) -> 1 | I9: =VLOOKUP(working_table!$G9,order_items[[#All],[product_id]:[subtotal_idr]],3,0) -> 119000 | J9: =VLOOKUP(working_table!$G9,order_items[[#All],[product_id]:[subtotal_idr]],4,0) -> 119000 | K9: =VLOOKUP($G9,products7[#All],2,0) -> Syal Rajut Senja Wear | L9: =VLOOKUP($G9,products7[#All],3,0) -> Accessories | M9: =VLOOKUP($G9,products7[#All],7,0) -> Senja Wear
A10: ORD000005 | B10: =VLOOKUP(A10,orders[#All],3,0) -> 45138 | C10: =VLOOKUP($A10,orders[#All],9,0) -> cancelled | D10: =VLOOKUP($A10,orders[#All],5,0) -> Bandung | E10: =VLOOKUP($A10,orders[#All],6,0) -> Jawa Barat | F10: =VLOOKUP($A10,orders[#All],10,0) -> TANPA PROMO | G10: PRD239 | H10: =VLOOKUP(working_table!G10,order_items[[#All],[product_id]:[subtotal_idr]],2,0) -> 2 | I10: =VLOOKUP(working_table!$G10,order_items[[#All],[product_id]:[subtotal_idr]],3,0) -> 179000 | J10: =VLOOKUP(working_table!$G10,order_items[[#All],[product_id]:[subtotal_idr]],4,0) -> 358000 | K10: =VLOOKUP($G10,products7[#All],2,0) -> Jacket Hoodie NusaBrand | L10: =VLOOKUP($G10,products7[#All],3,0) -> Jacket | M10: =VLOOKUP($G10,products7[#All],7,0) -> NusaBrand
A11: ORD000006 | B11: =VLOOKUP(A11,orders[#All],3,0) -> 44693 | C11: =VLOOKUP($A11,orders[#All],9,0) -> returned | D11: =VLOOKUP($A11,orders[#All],5,0) -> Balikpapan | E11: =VLOOKUP($A11,orders[#All],6,0) -> Kalimantan Timur | F11: =VLOOKUP($A11,orders[#All],10,0) -> TANPA PROMO | G11: PRD170 | H11: =VLOOKUP(working_table!G11,order_items[[#All],[product_id]:[subtotal_idr]],2,0) -> 1 | I11: =VLOOKUP(working_table!$G11,order_items[[#All],[product_id]:[subtotal_idr]],3,0) -> 349000 | J11: =VLOOKUP(working_table!$G11,order_items[[#All],[product_id]:[subtotal_idr]],4,0) -> 349000 | K11: =VLOOKUP($G11,products7[#All],2,0) -> Kemeja Oxford BajuKita | L11: =VLOOKUP($G11,products7[#All],3,0) -> Kemeja | M11: =VLOOKUP($G11,products7[#All],7,0) -> BajuKita
A12: ORD000007 | B12: =VLOOKUP(A12,orders[#All],3,0) -> 44597 | C12: =VLOOKUP($A12,orders[#All],9,0) -> delivered | D12: =VLOOKUP($A12,orders[#All],5,0) -> Bekasi | E12: =VLOOKUP($A12,orders[#All],6,0) -> Jawa Barat | F12: =VLOOKUP($A12,orders[#All],10,0) -> TANPA PROMO | G12: PRD013 | H12: =VLOOKUP(working_table!G12,order_items[[#All],[product_id]:[subtotal_idr]],2,0) -> 1 | I12: =VLOOKUP(working_table!$G12,order_items[[#All],[product_id]:[subtotal_idr]],3,0) -> 149000 | J12: =VLOOKUP(working_table!$G12,order_items[[#All],[product_id]:[subtotal_idr]],4,0) -> 149000 | K12: =VLOOKUP($G12,products7[#All],2,0) -> Pants Cargo NusaBrand | L12: =VLOOKUP($G12,products7[#All],3,0) -> Pants | M12: =VLOOKUP($G12,products7[#All],7,0) -> NusaBrand
A13: ORD000007 | B13: =VLOOKUP(A13,orders[#All],3,0) -> 44597 | C13: =VLOOKUP($A13,orders[#All],9,0) -> delivered | D13: =VLOOKUP($A13,orders[#All],5,0) -> Bekasi | E13: =VLOOKUP($A13,orders[#All],6,0) -> Jawa Barat | F13: =VLOOKUP($A13,orders[#All],10,0) -> TANPA PROMO | G13: PRD230 | H13: =VLOOKUP(working_table!G13,order_items[[#All],[product_id]:[subtotal_idr]],2,0) -> 2 | I13: =VLOOKUP(working_table!$G13,order_items[[#All],[product_id]:[subtotal_idr]],3,0) -> 129000 | J13: =VLOOKUP(working_table!$G13,order_items[[#All],[product_id]:[subtotal_idr]],4,0) -> 258000 | K13: =VLOOKUP($G13,products7[#All],2,0) -> Topi Baseball NusaBrand | L13: =VLOOKUP($G13,products7[#All],3,0) -> Accessories | M13: =VLOOKUP($G13,products7[#All],7,0) -> NusaBrand
... A4987: ORD003000 | B4987: =VLOOKUP(A4987,orders[#All],3,0) -> 45434 | C4987: =VLOOKUP($A4987,orders[#All],9,0) -> returned | D4987: =VLOOKUP($A4987,orders[#All],5,0) -> Depok | E4987: =VLOOKUP($A4987,orders[#All],6,0) -> Jawa Barat | F4987: =VLOOKUP($A4987,orders[#All],10,0) -> RAMADAN23 | G4987: PRD117 | H4987: =VLOOKUP(working_table!G4987,order_items[[#All],[product_id]:[subtotal_idr]],2,0) -> 2 | I4987: =VLOOKUP(working_table!$G4987,order_items[[#All],[product_id]:[subtotal_idr]],3,0) -> 49000 | J4987: =VLOOKUP(working_table!$G4987,order_items[[#All],[product_id]:[subtotal_idr]],4,0) -> 98000 | K4987: =VLOOKUP($G4987,products7[#All],2,0) -> Jacket Coach Ratu Mode | L4987: =VLOOKUP($G4987,products7[#All],3,0) -> Jacket | M4987: =VLOOKUP($G4987,products7[#All],7,0) -> Ratu Mode

Sheet Dashboard
A3: GAYANARA SALES PERFORMANCE DASHBOARD
AF5: =GETPIVOTDATA("total_amount_idr",Sheet4!$A$5) -> 877752049
H6: y
AE9: REVENUE
AE10: =Sheet4!$A$6 -> 877752049
AE13: ORDERS
AE14: =Sheet4!$A$12 -> 1776
AE18: AOV
AE19: =Sheet4!$A$17 -> 494229.76
AF23: Cancel Rate
AF24: =Sheet4!$C$24 -> 0.10933333
AG28: Return Rate
AG29: =GETPIVOTDATA("Count of order_id2",Sheet4!$A$23,"order_status","returned") -> 0.050333333

Sheet Sheet4
A2: Total Revenue delivered orders
A3: order_status | B3: delivered
A5: Sum of total_amount_idr
A6: 877752049
A8: Total Orders delivered orders
A9: order_status | B9: delivered
A11: Count of order_id
A12: 1776
A15: AOV delivered orders
A16: order_status | B16: delivered
A17: =GETPIVOTDATA("total_amount_idr",$A$5)/GETPIVOTDATA("order_id",$A$11) -> 494229.76
A22: Cancellation Rate
A23: Row Labels | B23: Count of order_id | C23: Count of order_id2
A24: cancelled | B24: 328 | C24: 0.10933333
A25: delivered | B25: 1776 | C25: 0.592
A26: processing | B26: 300 | C26: 0.1
A27: returned | B27: 151 | C27: 0.050333333
A28: shipped | B28: 445 | C28: 0.14833333
A29: Grand Total | B29: 3000 | C29: 1
A37: Monthly Revenue Delivered
A38: order_status | B38: delivered
A40: Row Labels | B40: Sum of total_amount_idr
A41: 2022 | B41: 137684793
A42: Jan | B42: 14747223
A43: Feb | B43: 7834402
A44: Mar | B44: 16463376
A45: Apr | B45: 14704793
A46: May | B46: 10446542
A47: Jun | B47: 7380707
A48: Jul | B48: 11589836
A49: Aug | B49: 6521264
A50: Sep | B50: 9077562
A51: Oct | B51: 11613315
A52: Nov | B52: 12792884
... A83: Grand Total | B83: 877752049
A97: order_status | B97: delivered
A99: Row Labels | B99: Sum of total_amount_idr | C99: Count of order_id | D99: Sum of total_amount_idr2 | E99: Average of total_amount_idr3
A100: SALE2024 | B100: 49301571 | C100: 91 | D100: 0.056167993 | E100: 541775.51
A101: TANPA PROMO | B101: 540219000 | C101: 1059 | D101: 0.61545741 | E101: 510121.81
A102: HARI BELANJA | B102: 45026734 | C102: 89 | D102: 0.051297783 | E102: 505918.36
...

Sheet Sheet7
A4: Top 10 Produk Delivered
A5: order_status | B5: returned | L5: Revenue By Cities
L6: order_status | M6: returned
A7: Row Labels | B7: Sum of quantity
A8: Dress Wrap BajuKita | B8: 9 | L8: Row Labels | M8: Sum of sub_total_idr
A9: T-Shirt Oversize BajuKita | B9: 7 | L9: Tangerang | M9: 7245000
A10: Jacket Denim Ratu Mode | B10: 7 | L10: Makassar | M10: 6113000
A11: Ikat Pinggang Kulit Pesona Indo | B11: 6 | L11: Manado | M11: 5833000
A12: Pants Kulot Cendana Co | B12: 6 | L12: Depok | M12: 5706000
A13: Kemeja Linen Senja Wear | B13: 6 | L13: Jakarta | M13: 5498000
A14: T-Shirt Raglan BajuKita | B14: 6 | L14: Pekanbaru | M14: 5309000
A15: Dress Mini Casual Riang Apparel | B15: 6 | L15: Bandung | M15: 5180000
A16: Dompet Kulit Ratu Mode | B16: 6 | L16: Pontianak | M16: 4967000
A17: Jacket Denim Tropika Style | B17: 6 | L17: Bekasi | M17: 4378000
A18: Jacket Denim Senja Wear | B18: 6 | L18: Medan | M18: 4255000
A19: Grand Total | B19: 71 | L19: Grand Total | M19: 54484000
A22: Top 10 Produk Best Revenue
A23: order_status | B23: returned
L24: Revenue By Province
A25: Row Labels | B25: Sum of sub_total_idr | L25: order_status | M25: returned | P25: Revenue By Category
A26: Dress Wrap Pesona Indo | B26: 2396000 | P26: order_status | Q26: returned
A27: Jacket Denim Tropika Style | B27: 2394000 | L27: Row Labels | M27: Sum of sub_total_idr
A28: Jacket Parasut Riang Apparel | B28: 2196000 | L28: Jawa Barat | M28: 16985000 | P28: Row Labels | Q28: Sum of sub_total_idr
A29: Pants Kulot Cendana Co | B29: 2034000 | L29: Banten | M29: 7245000 | P29: Jacket | Q29: 17496000
A30: Jacket Coach Senja Wear | B30: 1996000 | L30: Sulawesi Selatan | M30: 6113000 | P30: T-Shirt | Q30: 14452000
A31: Dress Midi Floral NusaBrand | B31: 1797000 | L31: Sulawesi Utara | M31: 5833000 | P31: dress | Q31: 12751000
A32: T-Shirt Graphic Pesona Indo | B32: 1796000 | L32: DKI Jakarta | M32: 5498000 | P32: Pants | Q32: 11733000
A33: Kemeja Batik BajuKita | B33: 1695000 | L33: Riau | M33: 5309000 | P33: Accessories | Q33: 11160000
A34: Jacket Bomber Senja Wear | B34: 1647000 | L34: Kalimantan Barat | M34: 4967000 | P34: Kemeja | Q34: 10687000
A35: T-Shirt Striped Kanvas Lokal | B35: 1626000 | L35: Sumatera Utara | M35: 4255000 | P35: Grand Total | Q35: 78279000
A36: Grand Total | B36: 19577000 | L36: Bali | M36: 4242000
L37: Kalimantan Timur | M37: 3923000
L38: Kalimantan Selatan | M38: 3496000
L39: Sumatera Selatan | M39: 3396000
L40: Jawa Timur | M40: 3081000
A41: Revenue By Brand | L41: Jawa Tengah | M41: 2946000
A42: order_status | B42: returned | L42: DI Yogyakarta | M42: 684000
L43: Sumatera Barat | M43: 306000
A44: Row Labels | B44: Sum of sub_total_idr | L44: Grand Total | M44: 78279000
A45: Cendana Co | B45: 10888000
...
